version: "3.8"
services:
  backend-flask:
    environment:
      FRONTEND_URL: "https://3000-${GITPOD_WORKSPACE_ID}.${GITPOD_WORKSPACE_CLUSTER_HOST}"
      BACKEND_URL: "https://4567-${GITPOD_WORKSPACE_ID}.${GITPOD_WORKSPACE_CLUSTER_HOST}"
    build: ./backend-flask
    ports:
      - "4567:4567"
    volumes:
      - ./backend-flask:/backend-flask
    healthcheck:
      test: curl --fail https://4567-${GITPOD_WORKSPACE_ID}.${GITPOD_WORKSPACE_CLUSTER_HOST} || exit 1
      interval: 60s
      retries: 5
      start_period: 20s
      timeout: 10s    
  frontend-react-js:
    environment:
      REACT_APP_BACKEND_URL: "https://4567-${GITPOD_WORKSPACE_ID}.${GITPOD_WORKSPACE_CLUSTER_HOST}"
    build: ./frontend-react-js
    ports:
      - "3000:3000"
    volumes:
      - ./frontend-react-js:/frontend-react-js
    healthcheck:
      test: curl --fail https://4567-${GITPOD_WORKSPACE_ID}.${GITPOD_WORKSPACE_CLUSTER_HOST} || exit 1
      interval: 60s
      retries: 5
      start_period: 20s
      timeout: 10s    

  dynamodb-local:
    # https://stackoverflow.com/questions/67533058/persist-local-dynamodb-data-in-volumes-lack-permission-unable-to-open-databa
    # We needed to add user:root to get this working.
    user: root
    command: "-jar DynamoDBLocal.jar -sharedDb -dbPath ./data"
    image: "amazon/dynamodb-local:latest"
    container_name: dynamodb-sde
    ports:
      - "8000:8000"
    volumes:
      - "./docker/dynamodb:/home/dynamodblocal/data"
    working_dir: /home/dynamodblocal

  db:
    image: postgres:13-alpine
    restart: always
    environment:
      - POSTGRES_USER=postgres
      - POSTGRES_PASSWORD=password
    ports:
      - '5432:5432'
    volumes: 
      - db:/var/lib/postgresql/data

networks: 
  internal-network:
    driver: bridge
    name: delyourhistorylocalhost
    
volumes:
  db:
    driver: local
